Workbook

Sheet kas
A1: TANGGAL | B1: KETERANGAN | C1: PEMASUKAN | D1: PENGELUARAN | E1: SALDO
B2: Saldo Akhir Desember 2025 | C2: -334000 | E2: =C2-F2 -> -334000
A3: 46023 | B3: Perawatan bibit tanaman untuk lapang utama : Pembelian tanah lembang | D3: 100000 | E3: =E2+C3-D3 -> -434000
B4: Pembelian sekam & polybag | D4: 90000 | E4: =E3+C4-D4 -> -524000
B5: Konsumsi | D5: 40000 | E5: =E4+C5-D5 -> -564000
A6: 46026 | B6: Kopi & gula ronda RW | D6: 51000 | E6: =E5+C6-D6 -> -615000
A7: 46031 | B7: Kertas karton untuk kartu iuran warung dan iuran RT | D7: 5000 | E7: =E6+C7-D7 -> -620000
B8: Retribusi warung & garasi | C8: 110000 | E8: =E7+C8-D8 -> -510000
A9: 46033 | B9: Donasi warga untuk pekerjaan lapangan utama | C9: 600000 | E9: =E8+C9-D9 -> 90000
B10: Pembelian busi & bensin mesin potong rumput | D10: 35000 | E10: =E9+C10-D10 -> 55000
A11: 46036 | B11: Giat Posyandu Jan'26 | D11: 250000 | E11: =E10+C11-D11 -> -195000
A12: 46039 | B12: Kontribusi KSM Jan'26 | C12: 250000 | E12: =E11+C12-D12 -> 55000
B13: Penggantian sisa semen 3 zak | C13: 200000 | E13: =E12+C13-D13 -> 255000
A14: 46041 | B14: Konsumsi rapat pengurus RW dengan pengurus RT | D14: 45000 | E14: =E13+C14-D14 -> 210000
B15: Kopi & gula ronda RW | D15: 46500 | E15: =E14+C15-D15 -> 163500
A16: 46043 | B16: Konsumsi rapat pengurus RT, RW dengan Kades | D16: 150000 | E16: =E15+C16-D16 -> 13500
A17: 46046 | B17: Konsumsi rapat laporan akhir tahunan kepengurusan RW periode 2025 | D17: 341000 | E17: =E16+C17-D17 -> -327500 | G17: 126000 | H17: Pak Agus
A18: 46047 | B18: Retribusi warung & garasi | C18: 926000 | E18: =E17+C18-D18 -> 598500 | G18: 932000 | H18: Pak Agus
A19: 46052 | B19: Iuran RT.001 - 007 Jan'26 | C19: 700000 | E19: =E18+C19-D19 -> 1298500 | G19: 257000 | H19: Pak Agus
B20: Denda ronda RW (RT.001 - 007) periode 26 Des'25 - 25 Jan'26 | C20: 760000 | E20: =E19+C20-D20 -> 2058500 | G20: 1400000 | H20: Pak Ali
B21: Kopi & gula ronda RW | D21: 46500 | E21: =E20+C21-D21 -> 2012000 | G21: 250000 | H21: Pak Dedi
A22: 46057 | B22: Retribusi warung & garasi | C22: 110000 | E22: =E21+C22-D22 -> 2122000
A23: 46060 | B23: Retribusi warung & garasi | C23: 354000 | E23: =E22+C23-D23 -> 2476000
A24: 46064 | B24: Giat Posyandu Feb'26 | D24: 250000 | E24: =E23+C24-D24 -> 2226000
B25: Penggantian sisa semen 2 zak | C25: 130000 | E25: =E24+C25-D25 -> 2356000
A26: 46066 | B26: Konsumsi rapat rencana bazar Ramadhan | D26: 26000 | E26: =E25+C26-D26 -> 2330000
A27: 46071 | B27: Pengadaan lampu PJU 3 set | D27: 775000 | E27: =E26+C27-D27 -> 1555000
A28: 46072 | B28: Kontribusi KSM Feb'26 | C28: 250000 | E28: =E27+C28-D28 -> 1805000
B29: Kopi & gula ronda RW | D29: 53000 | E29: =E28+C29-D29 -> 1752000
A30: 46074 | B30: Retribusi warung & garasi | C30: 1183000 | E30: =E29+C30-D30 -> 2935000
A31: 46080 | B31: Konsumsi rapat RW dengan pengurus RT | D31: 37000 | E31: =E30+C31-D31 -> 2898000
A32: 46081 | B32: Iuran RT.001 - 007 Feb'26 | C32: 700000 | E32: =E31+C32-D32 -> 3598000
B33: Denda ronda RW (RT.001 - 007) periode 26 Jan - 25 Feb'26 | C33: 400000 | E33: =E32+C33-D33 -> 3998000
A34: 46082 | B34: Pembelian kabel untuk lampu PJU | D34: 52000 | E34: =E33+C34-D34 -> 3946000
A35: 46083 | B35: Retribusi warung & garasi | C35: 110000 | E35: =E34+C35-D35 -> 4056000
A36: 46084 | B36: Retribusi warung & garasi | C36: 97000 | E36: =E35+C36-D36 -> 4153000
B37: Subsidi biaya tambah daya KWH meter pos ronda RW | D37: 50000 | E37: =E36+C37-D37 -> 4103000
A38: 46085 | B38: Konsumsi rapat dengan pengurus RT | D38: 25000 | E38: =E37+C38-D38 -> 4078000
A39: 46086 | B39: Kopi & gula ronda RW | D39: 53000 | E39: =E38+C39-D39 -> 4025000
A40: 46092 | B40: Giat Posyandu Mar'26 | D40: 250000 | E40: =E39+C40-D40 -> 3775000
...

Sheet Jan'26
A1: LAPORAN KEUANGAN RW.014 GRIYA PERMATA RAYA
A2: Periode : Januari 2026
A3: Tgl | B3: Keterangan | C3: Pemasukan | D3: Pengeluaran | E3: Saldo
A4: Saldo Akhir Desember 2025 | C4: -334000 | E4: =C4-F4 -> -334000
A5: 46023 | B5: Perawatan bibit tanaman untuk lapang utama : Pembelian tanah lembang | D5: 100000 | E5: =E4+C5-D5 -> -434000
B6: Pembelian sekam & polybag | D6: 90000 | E6: =E5+C6-D6 -> -524000
B7: Konsumsi | D7: 40000 | E7: =E6+C7-D7 -> -564000
A8: 46026 | B8: Kopi & gula ronda RW | D8: 51000 | E8: =E7+C8-D8 -> -615000
A9: 46031 | B9: Kertas karton untuk kartu iuran warung dan iuran RT | D9: 5000 | E9: =E8+C9-D9 -> -620000
B10: Retribusi warung & garasi | C10: 110000 | E10: =E9+C10-D10 -> -510000
A11: 46033 | B11: Donasi warga untuk pekerjaan lapangan utama | C11: 600000 | E11: =E10+C11-D11 -> 90000
B12: Pembelian busi & bensin mesin potong rumput | D12: 35000 | E12: =E11+C12-D12 -> 55000
A13: 46036 | B13: Giat Posyandu Jan'26 | D13: 250000 | E13: =E12+C13-D13 -> -195000
A14: 46039 | B14: Kontribusi KSM Jan'26 | C14: 250000 | E14: =E13+C14-D14 -> 55000
B15: Penggantian sisa semen 3 zak | C15: 200000 | E15: =E14+C15-D15 -> 255000
A16: 46041 | B16: Konsumsi rapat pengurus RW dengan pengurus RT | D16: 45000 | E16: =E15+C16-D16 -> 210000
B17: Kopi & gula ronda RW | D17: 46500 | E17: =E16+C17-D17 -> 163500
A18: 46043 | B18: Konsumsi rapat pengurus RT, RW dengan Kades | D18: 150000 | E18: =E17+C18-D18 -> 13500
A19: 46046 | B19: Konsumsi rapat laporan akhir tahunan kepengurusan RW periode 2025 | D19: 341000 | E19: =E18+C19-D19 -> -327500 | G19: 126000 | H19: Pak Agus
A20: 46047 | B20: Retribusi warung & garasi | C20: 926000 | E20: =E19+C20-D20 -> 598500 | G20: 932000 | H20: Pak Agus
A21: 46052 | B21: Iuran RT.001 - 007 Jan'26 | C21: 700000 | E21: =E20+C21-D21 -> 1298500 | G21: 257000 | H21: Pak Agus
B22: Denda ronda RW (RT.001 - 007) periode 26 Des'25 - 25 Jan'26 | C22: 760000 | E22: =E21+C22-D22 -> 2058500 | G22: 1400000 | H22: Pak Ali
B23: Kopi & gula ronda RW | D23: 46500 | E23: =E22+C23-D23 -> 2012000 | G23: 250000 | H23: Pak Dedi
A24: Total Keuangan Januari 2026 | C24: =SUM(C4:C23) -> 3212000 | D24: =SUM(D4:D23) -> 1200000 | E24: =C24-D24 -> 2012000 | G24: =SUM(G19:G23) -> 2965000
A26: JUMLAH PEMASUKAN JANUARI 2026 | C26: =C24-C4 -> 3546000 | G26: =E24-G24 -> -953000
A28: JUMLAH PENGELUARAN JANUARI 2026 | C28: =D24 -> 1200000
D30: Rancaekek, 10 Februari 2026
A31: Mengetahui | D31: Penyusun
A34: Agus Hendra | D34: Aan Toni F
A35: Ketua RT | D35: Bendahara RT

Sheet Feb'26
A1: LAPORAN KEUANGAN RW.014 GRIYA PERMATA RAYA
A2: Periode : Februari 2026
A3: Tgl | B3: Keterangan | C3: Pemasukan | D3: Pengeluaran | E3: Saldo
A4: Saldo Akhir Januari 2026 | C4: ='Jan''26'!E24 -> 2012000 | E4: =C4-F4 -> 2012000
A5: 46057 | B5: Retribusi warung & garasi | C5: 110000 | E5: =E4+C5-D5 -> 2122000
A6: 46060 | B6: Retribusi warung & garasi | C6: 354000 | E6: =E5+C6-D6 -> 2476000
A7: 46064 | B7: Giat Posyandu Feb'26 | D7: 250000 | E7: =E6+C7-D7 -> 2226000
B8: Penggantian sisa semen 2 zak | C8: 130000 | E8: =E7+C8-D8 -> 2356000
A9: 46066 | B9: Konsumsi rapat rencana bazar Ramadhan | D9: 26000 | E9: =E8+C9-D9 -> 2330000
A10: 46071 | B10: Pengadaan lampu PJU 3 set | D10: 775000 | E10: =E9+C10-D10 -> 1555000
A11: 46072 | B11: Kontribusi KSM Feb'26 | C11: 250000 | E11: =E10+C11-D11 -> 1805000
B12: Kopi & gula ronda RW | D12: 53000 | E12: =E11+C12-D12 -> 1752000 | G12: 126000 | H12: Pak Agus
A13: 46074 | B13: Retribusi warung & garasi | C13: 1183000 | E13: =E12+C13-D13 -> 2935000 | G13: 932000 | H13: Pak Agus
A14: 46080 | B14: Konsumsi rapat RW dengan pengurus RT | D14: 37000 | E14: =E13+C14-D14 -> 2898000 | G14: 257000 | H14: Pak Agus
A15: 46081 | B15: Iuran RT.001 - 007 Feb'26 | C15: 700000 | E15: =E14+C15-D15 -> 3598000 | G15: 1400000 | H15: Pak Ali
B16: Denda ronda RW (RT.001 - 007) periode 26 Jan - 25 Feb'26 | C16: 400000 | E16: =E15+C16-D16 -> 3998000 | G16: 250000 | H16: Pak Dedi
A17: Total Keuangan Februari 2026 | C17: =SUM(C4:C16) -> 5139000 | D17: =SUM(D4:D16) -> 1141000 | E17: =C17-D17 -> 3998000 | G17: =SUM(G12:G16) -> 2965000
A19: JUMLAH PEMASUKAN FEBRUARI 2026 | C19: =C17-C4 -> 3127000 | G19: =E17-G17 -> 1033000
A21: JUMLAH PENGELUARAN FEBRUARI 2026 | C21: =D17 -> 1141000
D23: Rancaekek, 06 Maret 2026
A24: Mengetahui | D24: Penyusun
A27: Agus Hendra | D27: Aan Toni F
A28: Ketua RT | D28: Bendahara RT

Sheet Bazar
A1: REKAP KEUANGAN BAZAR RAMADHAN 1447H/ 2026M
A2: RW.014 GRIYA PERMATA RAYA
A4: Tanggal | B4: Keterangan | C4: Pemasukan | D4: Pengeluaran | E4: Saldo | F4: Catatan
A5: 46072 | B5: Retribusi bazar hari 1 | C5: 140000 | E5: =C5 -> 140000
A6: 46073 | B6: Retribusi bazar hari 2 | C6: 160000 | E6: =E5+C6-D6 -> 300000
A7: 46074 | B7: Retribusi bazar hari 3 | C7: 164000 | E7: =E6+C7-D7 -> 464000
A8: 46075 | B8: Retribusi bazar hari 4 | C8: 120000 | E8: =E7+C8-D8 -> 584000
A9: 46076 | B9: Retribusi bazar hari 5 | C9: 132000 | E9: =E8+C9-D9 -> 716000
A10: 46077 | B10: Retribusi bazar hari 6 | C10: 136000 | E10: =E9+C10-D10 -> 852000
A11: 46078 | B11: Retribusi bazar hari 7 | C11: 120000 | E11: =E10+C11-D11 -> 972000
A12: 46078 | B12: Kebersihan bazar pekan I | D12: 75000 | E12: =E11+C12-D12 -> 897000
A13: 46079 | B13: Retribusi bazar hari 8 | C13: 140000 | E13: =E12+C13-D13 -> 1037000
A14: 46080 | B14: Retribusi bazar hari 9 | C14: 120000 | E14: =E13+C14-D14 -> 1157000
A15: 46081 | B15: Retribusi bazar hari 10 | C15: 120000 | E15: =E14+C15-D15 -> 1277000
A16: 46082 | B16: Retribusi bazar hari 11 | C16: 120000 | E16: =E15+C16-D16 -> 1397000
A17: 46083 | B17: Retribusi bazar hari 12 | C17: 120000 | E17: =E16+C17-D17 -> 1517000
A18: 46084 | B18: Retribusi bazar hari 13 | C18: 120000 | E18: =E17+C18-D18 -> 1637000
A19: 46085 | B19: Retribusi bazar hari 14 | C19: 120000 | E19: =E18+C19-D19 -> 1757000
A20: 46085 | B20: Kebersihan bazar pekan II | D20: 75000 | E20: =E19+C20-D20 -> 1682000
A21: 46086 | B21: Retribusi bazar hari 15 | C21: 120000 | E21: =E20+C21-D21 -> 1802000
A22: 46087 | B22: Retribusi bazar hari 16 | C22: 60000 | E22: =E21+C22-D22 -> 1862000
A23: 46088 | B23: Retribusi bazar hari 17 | C23: 100000 | E23: =E22+C23-D23 -> 1962000
A24: 46089 | B24: Retribusi bazar hari 18 | C24: 100000 | E24: =E23+C24-D24 -> 2062000
A25: 46090 | B25: Retribusi bazar hari 19 | C25: 100000 | E25: =E24+C25-D25 -> 2162000
A26: 46091 | B26: Retribusi bazar hari 20 | C26: 0 | E26: =E25+C26-D26 -> 2162000 | F26: Hujan
A27: 46092 | B27: Retribusi bazar hari 21 | C27: 0 | E27: =E26+C27-D27 -> 2162000 | F27: Hujan
A28: 46092 | B28: Kebersihan bazar pekan III | D28: 75000 | E28: =E27+C28-D28 -> 2087000
A29: 46093 | B29: Retribusi bazar hari 22 | C29: 64000 | E29: =E28+C29-D29 -> 2151000
A30: 46094 | B30: Retribusi bazar hari 23 | C30: 100000 | E30: =E29+C30-D30 -> 2251000
A31: 46095 | B31: Retribusi bazar hari 24 | C31: 0 | E31: =E30+C31-D31 -> 2251000 | F31: Hujan
A32: 46096 | B32: Retribusi bazar hari 25 | C32: 88000 | E32: =E31+C32-D32 -> 2339000
A33: 46097 | B33: Retribusi bazar hari 26 | C33: 0 | E33: =E32+C33-D33 -> 2339000 | F33: Dikelola Pemuda
A34: 46098 | B34: Retribusi bazar hari 27 | C34: 0 | E34: =E33+C34-D34 -> 2339000 | F34: Dikelola Pemuda
A35: 46099 | B35: Retribusi bazar hari 28 | C35: 0 | E35: =E34+C35-D35 -> 2339000 | F35: Dikelola Pemuda
A36: 46100 | B36: Retribusi bazar hari 29 | C36: 0 | E36: =E35+C36-D36 -> 2339000 | F36: Dikelola Pemuda
A37: 46101 | B37: Retribusi bazar hari 30 | C37: 0 | E37: =E36+C37-D37 -> 2339000 | F37: Dikelola Pemuda
A38: 46101 | B38: Kebersihan bazar pekan IV | D38: 100000 | E38: =E37+C38-D38 -> 2239000
A39: 46101 | B39: Kadeudeuh koordinator kebersihan | D39: 250000 | E39: =E38+C39-D39 -> 1989000
A40: 46111 | B40: Pengadaan rompi RW | D40: 300000 | E40: =E39+C40-D40 -> 1689000
A41: Total | C41: =SUM(C5:C40) -> 2564000 | D41: =SUM(D5:D40) -> 875000 | E41: =C41-D41 -> 1689000

Sheet Mar'26
A1: LAPORAN KEUANGAN RW.014 GRIYA PERMATA RAYA
A2: Periode : Maret 2026
A3: Tgl | B3: Keterangan | C3: Pemasukan | D3: Pengeluaran | E3: Saldo
A4: Saldo Akhir Februari 2026 | C4: ='Feb''26'!E17 -> 3998000 | E4: =C4-F4 -> 3998000
A5: 46082 | B5: Pembelian kabel untuk lampu PJU | D5: 52000 | E5: =E4+C5-D5 -> 3946000
A6: 46083 | B6: Retribusi warung & garasi | C6: 110000 | E6: =E5+C6-D6 -> 4056000
A7: 46084 | B7: Retribusi warung & garasi | C7: 97000 | E7: =E6+C7-D7 -> 4153000
B8: Subsidi biaya tambah daya KWH meter pos ronda RW | D8: 50000 | E8: =E7+C8-D8 -> 4103000
A9: 46085 | B9: Konsumsi rapat dengan pengurus RT | D9: 25000 | E9: =E8+C9-D9 -> 4078000
A10: 46086 | B10: Kopi & gula ronda RW | D10: 53000 | E10: =E9+C10-D10 -> 4025000
A11: 46092 | B11: Giat Posyandu Mar'26 | D11: 250000 | E11: =E10+C11-D11 -> 3775000
A12: 46095 | B12: Kontribusi KSM Mar'26 | C12: 250000 | E12: =E11+C12-D12 -> 4025000
A13: 46096 | B13: Pembelian tambahan kabel lampu PJU | D13: 45000 | E13: =E12+C13-D13 -> 3980000
B14: Retribusi warung & garasi | C14: 701000 | E14: =E13+C14-D14 -> 4681000
A15: 46101 | B15: Konsumsi rapat dengan Pemuda | D15: 50000 | E15: =E14+C15-D15 -> 4631000
B16: Retribusi bazar Ramadhan | C16: 1689000 | E16: =E15+C16-D16 -> 6320000
A17: 46107 | B17: Konsumsi giat kebersihan di lapangan utama | D17: 20000 | E17: =E16+C17-D17 -> 6300000
B18: Pembelian busi mesin potong rumput | D18: 40000 | E18: =E17+C18-D18 -> 6260000
B19: Penyerahan kontribusi giat Halal Bihalal kepada DKM UBK | D19: 2000000 | E19: =E18+C19-D19 -> 4260000
A20: 46109 | B20: Pembelian bensin mesin potong rumput | D20: 24000 | E20: =E19+C20-D20 -> 4236000 | G20: 126000 | H20: Pak Agus
B21: Konsumsi giat kebersihan di lapangan utama | D21: 36000 | E21: =E20+C21-D21 -> 4200000 | G21: 932000 | H21: Pak Agus
A22: 46110 | B22: Kopi & gula ronda RW | D22: 44500 | E22: =E21+C22-D22 -> 4155500 | G22: 257000 | H22: Pak Agus
A23: 46112 | B23: Iuran RT.001 - 007 Mar'26 | C23: 700000 | E23: =E22+C23-D23 -> 4855500 | G23: 1400000 | H23: Pak Ali
B24: Denda ronda RW (RT.001 - 007) periode 26 Feb - 25 Mar'26 | C24: 300000 | E24: =E23+C24-D24 -> 5155500 | G24: 250000 | H24: Pak Dedi
A25: Total Keuangan Maret 2026 | C25: =SUM(C4:C24) -> 7845000 | D25: =SUM(D4:D24) -> 2689500 | E25: =C25-D25 -> 5155500 | G25: =SUM(G20:G24) -> 2965000
A27: JUMLAH PEMASUKAN MARET 2026 | C27: =C25-C4 -> 3847000 | G27: =E25-G25 -> 2190500
A29: JUMLAH PENGELUARAN MARET 2026 | C29: =D25 -> 2689500
D31: Rancaekek, 10 April 2026
A32: Mengetahui | D32: Penyusun
A35: Agus Hendra | D35: Aan Toni F
A36: Ketua RT | D36: Bendahara RT

Sheet Apr'26
A1: LAPORAN KEUANGAN RW.014 GRIYA PERMATA RAYA
A2: Periode : April 2026
A3: Tgl | B3: Keterangan | C3: Pemasukan | D3: Pengeluaran | E3: Saldo
A4: Saldo Akhir Maret 2026 | C4: ='Mar''26'!E25 -> 5155500 | E4: =C4-F4 -> 5155500
A5: 46114 | B5: Retribusi warung & garasi | C5: 110000 | E5: =E4+C5-D5 -> 5265500
A6: 46118 | B6: Giat Posyandu Apr'26 | D6: 250000 | E6: =E5+C6-D6 -> 5015500
A7: 46122 | B7: Kopi & gula ronda RW | D7: 46500 | E7: =E6+C7-D7 -> 4969000
A8: 46130 | B8: Retribusi warung & garasi | C8: 1080000 | E8: =E7+C8-D8 -> 6049000
A9: 46131 | B9: Kopi & gula ronda RW | D9: 55500 | E9: =E8+C9-D9 -> 5993500
A10: 46132 | B10: Kontribusi KSM Apr'26 | C10: 250000 | E10: =E9+C10-D10 -> 6243500 | G10: 126000 | H10: Pak Agus
B11: Konsumsi rapat dengan pengurus RT | D11: 60000 | E11: =E10+C11-D11 -> 6183500 | G11: 932000 | H11: Pak Agus
A12: 46134 | B12: Konsumsi Muswe perihal pengelolaan sampah | D12: 200000 | E12: =E11+C12-D12 -> 5983500 | G12: 257000 | H12: Pak Agus
A13: 46136 | B13: Retribusi warung & garasi | C13: 189000 | E13: =E12+C13-D13 -> 6172500 | G13: 1400000 | H13: Pak Ali
A14: 46140 | B14: Konsumi rapat Pengurus RT, RW, dan Kades | D14: 140000 | E14: =E13+C14-D14 -> 6032500 | G14: 250000 | H14: Pak Dedi
A15: Total Keuangan April 2026 | C15: =SUM(C4:C14) -> 6784500 | D15: =SUM(D4:D14) -> 752000 | E15: =C15-D15 -> 6032500 | G15: =SUM(G10:G14) -> 2965000
A17: JUMLAH PEMASUKAN APRIL 2026 | C17: =C15-C4 -> 1629000 | G17: =E15-G15 -> 3067500
A19: JUMLAH PENGELUARAN APRIL 2026 | C19: =D15 -> 752000
D21: Rancaekek, 05 Mei 2026
A22: Mengetahui | D22: Penyusun
A25: Agus Hendra | D25: Aan Toni F
A26: Ketua RT | D26: Bendahara RT

Sheet Mei'26
A1: LAPORAN KEUANGAN RW.014 GRIYA PERMATA RAYA
A2: Periode : Mei 2026
A3: Tgl | B3: Keterangan | C3: Pemasukan | D3: Pengeluaran | E3: Saldo
A4: Saldo Akhir April 2026 | C4: ='Apr''26'!E15 -> 6032500 | E4: =C4-F4 -> 6032500
A5: 46144 | B5: Retribusi warung & garasi | C5: 110000 | E5: =E4+C5-D5 -> 6142500
A6: 46145 | B6: Iuran RT.001 - 007 April'26 | C6: 700000 | E6: =E5+C6-D6 -> 6842500
B7: Denda ronda RW (RT.001 - 007) periode 26 Mar - 25 April'26 | C7: 480000 | E7: =E6+C7-D7 -> 7322500
A8: 46147 | B8: Konsumsi rapat Pengurus RW dengan Pengurus RT | D8: 57000 | E8: =E7+C8-D8 -> 7265500
A9: 46148 | B9: Biaya penarikan I sampah oleh Bumdes Cimanggung | D9: 916000 | E9: =E8+C9-D9 -> 6349500
B10: Kopi & gula ronda RW | D10: 42500 | E10: =E9+C10-D10 -> 6307000
A11: 46151 | B11: Konsumsi pembersihan lapangan utama | D11: 100000 | E11: =E10+C11-D11 -> 6207000
B12: Busi mesin potong rumput | D12: 20000 | E12: =E11+C12-D12 -> 6187000
A13: 46154 | B13: Konsumsi rapat Pengurus RW dengan Pengurus RT | D13: 34000 | E13: =E12+C13-D13 -> 6153000
A14: 46155 | B14: Giat Posyandu Mei'26 | D14: 250000 | E14: =E13+C14-D14 -> 5903000
B15: Biaya penarikan II sampah oleh Bumdes Cimanggung | D15: 1000000 | E15: =E14+C15-D15 -> 4903000
A16: 46158 | B16: Retribusi warung & garasi | C16: 1045000 | E16: =E15+C16-D16 -> 5948000
B17: Kontribusi Yayasan UBK (air bersih) | C17: 250000 | E17: =E16+C17-D17 -> 6198000 | G17: 126000 | H17: Pak Agus
A18: 46160 | B18: Retribusi warung & garasi | C18: 100000 | E18: =E17+C18-D18 -> 6298000 | G18: 932000 | H18: Pak Agus
A19: 46162 | B19: Konsumsi rapat Pengurus RW dengan Pengurus RT | D19: 25000 | E19: =E18+C19-D19 -> 6273000 | G19: 257000 | H19: Pak Agus
A20: 46165 | B20: Kopi & gula ronda RW | D20: 51000 | E20: =E19+C20-D20 -> 6222000 | G20: 1400000 | H20: Pak Ali
B21: Retribusi warung & garasi | C21: 115000 | E21: =E20+C21-D21 -> 6337000 | G21: 250000 | H21: Pak Dedi
A22: Total Keuangan Mei 2026 | C22: =SUM(C4:C21) -> 8832500 | D22: =SUM(D4:D21) -> 2495500 | E22: =C22-D22 -> 6337000 | G22: =SUM(G17:G21) -> 2965000
A24: JUMLAH PEMASUKAN MEI 2026 | C24: =C22-C4 -> 2800000 | G24: =E22-G22 -> 3372000
A26: JUMLAH PENGELUARAN MEI 2026 | C26: =D22 -> 2495500
D28: Rancaekek, 12 Juni 2026
A29: Mengetahui | D29: Penyusun
A32: Triyadi Sucipto | D32: Aan Toni F
A33: Ketua RW | D33: Bendahara RW

Sheet Juni'26
A1: LAPORAN KEUANGAN RW.014 GRIYA PERMATA RAYA
A2: Periode : Juni 2026
A3: Tgl | B3: Keterangan | C3: Pemasukan | D3: Pengeluaran | E3: Saldo
A4: Saldo Akhir Mei 2026 | C4: ='Mei''26'!E22 -> 6337000 | E4: =C4-F4 -> 6337000
A5: 46175 | B5: Iuran RT.001 - 007 Mei'26 | C5: 700000 | E5: =E4+C5-D5 -> 7037000
B6: Denda ronda RW (RT.001 - 007) periode 26 April - 25 Mei'26 | C6: 460000 | E6: =E5+C6-D6 -> 7497000
B7: Retribusi warung & garasi | C7: 150000 | E7: =E6+C7-D7 -> 7647000
A8: 46176 | B8: Kopi & gula ronda RW | D8: 42500 | E8: =E7+C8-D8 -> 7604500
A9: 46177 | B9: Retribusi warung & garasi | C9: 110000 | E9: =E8+C9-D9 -> 7714500
A10: 46178 | B10: Konsumsi rapat Pengurus RW dengan Pengurus RT | D10: 18000 | E10: =E9+C10-D10 -> 7696500
A11: 46180 | B11: Retribusi warung & garasi | C11: 204000 | E11: =E10+C11-D11 -> 7900500
A12: 46182 | B12: Giat Posyandu Juni 2026 | D12: 250000 | E12: =E11+C12-D12 -> 7650500
A13: 46183 | B13: Retribusi sampah RW periode Mei 2026 RT.001 | C13: 200000 | E13: =E12+C13-D13 -> 7850500
B14: Retribusi sampah RW periode Mei 2026 RT.002 | C14: 230000 | E14: =E13+C14-D14 -> 8080500
B15: Retribusi sampah RW periode Mei 2026 RT.003 | C15: 250000 | E15: =E14+C15-D15 -> 8330500
B16: Retribusi sampah RW periode Mei 2026 RT.004 | C16: 225000 | E16: =E15+C16-D16 -> 8555500
B17: Retribusi sampah RW periode Mei 2026 RT.005 | C17: 350000 | E17: =E16+C17-D17 -> 8905500
B18: Retribusi sampah RW periode Mei 2026 RT.006 | C18: 230000 | E18: =E17+C18-D18 -> 9135500
B19: Retribusi sampah RW periode Mei 2026 RT.007 | C19: 370000 | E19: =E18+C19-D19 -> 9505500
A20: 46186 | B20: Konsumsi rapat Pengurus RW, Pengurus RT dengan pihak Penarik Sampah | D20: 60000 | E20: =E19+C20-D20 -> 9445500
A21: 46187 | B21: Retribusi warung & garasi | C21: 250000 | E21: =E20+C21-D21 -> 9695500
A22: 46191 | B22: Retribusi warung & garasi | C22: 100000 | E22: =E21+C22-D22 -> 9795500
A23: 46193 | B23: Kopi + rokok penarik sampah | D23: 26000 | E23: =E22+C23-D23 -> 9769500 | G23: 132000 | H23: Survey jalan
A24: 46196 | B24: Biaya penarikan sampah (20 Juni & 04 Juli 2026 ) | D24: 2300000 | E24: =E23+C24-D24 -> 7469500 | G24: 126000 | H24: Pak Agus
A25: 46197 | B25: Kopi + gula ronda RW | D25: 25500 | E25: =E24+C25-D25 -> 7444000 | G25: 932000 | H25: Pak Agus
A26: 46200 | B26: Retribusi warung & garasi | C26: 990000 | E26: =E25+C26-D26 -> 8434000 | G26: 257000 | H26: Pak Agus
A27: 46203 | B27: Iuran RT.001 - 007 Juni'26 | C27: 700000 | E27: =E26+C27-D27 -> 9134000 | G27: 1400000 | H27: Pak Ali
B28: Denda ronda RW (RT.001 - 007) periode 26 Mei - 25 Juni'26 | C28: 500000 | E28: =E27+C28-D28 -> 9634000 | G28: 250000 | H28: Pak Dedi
A29: Total Keuangan Juni 2026 | C29: =SUM(C4:C28) -> 12356000 | D29: =SUM(D4:D28) -> 2722000 | E29: =C29-D29 -> 9634000 | G29: =SUM(G23:G28) -> 3097000
A31: JUMLAH PEMASUKAN JUNI 2026 | C31: =C29-C4 -> 6019000 | G31: =E29-G29 -> 6537000
A33: JUMLAH PENGELUARAN JUNI 2026 | C33: =D29 -> 2722000
D35: Rancaekek, 07 Juli 2026
A36: Mengetahui | D36: Penyusun
A39: Triyadi Sucipto | D39: Aan Toni F
A40: Ketua RW | D40: Bendahara RW

Sheet Juli'26
A1: LAPORAN KEUANGAN RW.014 GRIYA PERMATA RAYA
A2: Periode : Juli 2026
A3: Tgl | B3: Keterangan | C3: Pemasukan | D3: Pengeluaran | E3: Saldo
A4: Saldo Akhir Mei 2026 | C4: ='Juni''26'!E29 -> 9634000 | E4: =C4-F4 -> 9634000
A5: 46207 | B5: Retribusi warung & garasi | C5: 110000 | E5: =E4+C5-D5 -> 9744000
E6: =E5+C6-D6 -> 9744000
E7: =E6+C7-D7 -> 9744000
E8: =E7+C8-D8 -> 9744000
E9: =E8+C9-D9 -> 9744000
E10: =E9+C10-D10 -> 9744000
E11: =E10+C11-D11 -> 9744000
E12: =E11+C12-D12 -> 9744000
E13: =E12+C13-D13 -> 9744000
E14: =E13+C14-D14 -> 9744000
E15: =E14+C15-D15 -> 9744000
E16: =E15+C16-D16 -> 9744000
E17: =E16+C17-D17 -> 9744000
E18: =E17+C18-D18 -> 9744000 | G18: 132000 | H18: Survey jalan
E19: =E18+C19-D19 -> 9744000 | G19: 126000 | H19: Pak Agus
E20: =E19+C20-D20 -> 9744000 | G20: 932000 | H20: Pak Agus
E21: =E20+C21-D21 -> 9744000 | G21: 257000 | H21: Pak Agus
E22: =E21+C22-D22 -> 9744000 | G22: 1400000 | H22: Pak Ali
E23: =E22+C23-D23 -> 9744000 | G23: 250000 | H23: Pak Dedi
A24: Total Keuangan Juli 2026 | C24: =SUM(C4:C23) -> 9744000 | D24: =SUM(D4:D23) -> 0 | E24: =C24-D24 -> 9744000 | G24: =SUM(G18:G23) -> 3097000
A26: JUMLAH PEMASUKAN JULI 2026 | C26: =C24-C4 -> 110000 | G26: =E24-G24 -> 6647000
A28: JUMLAH PENGELUARAN JULI 2026 | C28: =D24 -> 0
D30: Rancaekek, 05 Agustus 2026
A31: Mengetahui | D31: Penyusun
A34: Triyadi Sucipto | D34: Aan Toni F
A35: Ketua RW | D35: Bendahara RW

Sheet Agust'26
A1: LAPORAN KEUANGAN RW.014 GRIYA PERMATA RAYA
A2: Periode : Agustus 2026
A3: Tgl | B3: Keterangan | C3: Pemasukan | D3: Pengeluaran | E3: Saldo
A4: Saldo Akhir April 2026 | C4: ='Apr''26'!E15 -> 6032500 | E4: =C4-F4 -> 6032500
E5: =E4+C5-D5 -> 6032500
E6: =E5+C6-D6 -> 6032500
E7: =E6+C7-D7 -> 6032500
E8: =E7+C8-D8 -> 6032500
E9: =E8+C9-D9 -> 6032500
E10: =E9+C10-D10 -> 6032500 | G10: 126000 | H10: Pak Agus
E11: =E10+C11-D11 -> 6032500 | G11: 932000 | H11: Pak Agus
E12: =E11+C12-D12 -> 6032500 | G12: 257000 | H12: Pak Agus
E13: =E12+C13-D13 -> 6032500 | G13: 1400000 | H13: Pak Ali
E14: =E13+C14-D14 -> 6032500 | G14: 250000 | H14: Pak Dedi
A15: Total Keuangan Mei 2026 | C15: =SUM(C4:C14) -> 6032500 | D15: =SUM(D4:D14) -> 0 | E15: =C15-D15 -> 6032500 | G15: =SUM(G10:G14) -> 2965000
A17: JUMLAH PEMASUKAN MEI 2026 | C17: =C15-C4 -> 0 | G17: =E15-G15 -> 3067500
A19: JUMLAH PENGELUARAN MEI 2026 | C19: =D15 -> 0
G20: 4357500 | H20: =G17-G20 -> -1290000
D21: Rancaekek, 05 Juni 2026
A22: Mengetahui | D22: Penyusun
A25: Triyadi Sucipto | D25: Aan Toni F
A26: Ketua RW | D26: Bendahara RW

Sheet Rekap
A1: REKAP BIAYA PENGELOLAAN SAMPAH RW.014
A2: PERIODE MEI - JUNI 2026
A3: Tgl | B3: Keterangan | C3: Pemasukan | D3: Pengeluaran
A4: 46148 | B4: Biaya penarikan I sampah oleh Bumdes Cimanggung | D4: 916000
A5: 46155 | B5: Biaya penarikan II sampah oleh Bumdes Cimanggung | D5: 1000000
A6: 46183 | B6: Retribusi sampah RW periode Mei 2026 RT.001 | C6: 200000
A7: 46183 | B7: Retribusi sampah RW periode Mei 2026 RT.002 | C7: 230000
A8: 46183 | B8: Retribusi sampah RW periode Mei 2026 RT.003 | C8: 250000
A9: 46183 | B9: Retribusi sampah RW periode Mei 2026 RT.004 | C9: 225000
A10: 46183 | B10: Retribusi sampah RW periode Mei 2026 RT.005 | C10: 350000
A11: 46183 | B11: Retribusi sampah RW periode Mei 2026 RT.006 | C11: 230000
A12: 46183 | B12: Retribusi sampah RW periode Mei 2026 RT.007 | C12: 370000
A13: 46186 | B13: Konsumsi rapat Pengurus RW, Pengurus RT dengan pihak Penarik Sampah | D13: 60000
A14: 46193 | B14: Kopi + rokok penarik sampah | D14: 26000
A15: 46196 | B15: Biaya penarikan sampah (20 Juni & 04 Juli 2026 ) | D15: 2300000
C16: =SUM(C4:C15) -> 1855000 | D16: =SUM(D4:D15) -> 4302000
A20: REKAP KEUANGAN RW.014
A21: PERIODE JAN - JUNI 2026
A22: Bulan | B22: Pemasukan | C22: Pengeluaran
A23: Januari | B23: ='Jan''26'!C26 -> 3546000 | C23: ='Jan''26'!C28 -> 1200000
A24: Februari | B24: ='Feb''26'!C19 -> 3127000 | C24: ='Feb''26'!C21 -> 1141000
A25: Maret | B25: ='Mar''26'!C27 -> 3847000 | C25: ='Mar''26'!C29 -> 2689500
A26: April | B26: ='Apr''26'!C17 -> 1629000 | C26: ='Apr''26'!C19 -> 752000
A27: Mei | B27: ='Mei''26'!C24 -> 2800000 | C27: ='Mei''26'!C26 -> 2495500
A28: Juni | B28: ='Juni''26'!C31 -> 6019000 | C28: ='Juni''26'!C33 -> 2722000
A29: JUMLAH | B29: =SUM(B23:B28) -> 20968000 | C29: =SUM(C23:C28) -> 11000000
